---
title: feign调用失败后返回错误结果
date: 2022-03-03 17:02:04
tags:
- feign
- spring cloud
categories:
- develop
---

这又是一篇开发过程中遇到的问题，其实解决也很简单啦，spring的文档感觉还是挺全面的，[这里](https://cloud.spring.io/spring-cloud-netflix/multi/multi_spring-cloud-feign.html#spring-cloud-feign-hystrix-fallback)是对应的文档。


问题很简单，在我们的框架里边，内部接口调用用的是feign，然后就很正常的用了Hystrix来做服务降级，实现也很简单，在feign的注解上加上`fallback`的字段，然后在对应的降级类里边实现对应要返回的信息就好了。这就带来了一个小小的问题：原服务里边写好的错误就获取不到了，只能获取到Hystrix里边fallback函数抛出来的错误。

<!--more-->

其实也很好解决：在`FeignClient`里边可以加上`fallbackFactory`，然后修改原先的降级函数，实现`FallbackFactory<HystrixClient>`就好了。

看代码可能更简单？

没有实现`fallbackFactory`的版本：

```java
@FeignClient(name = "hello", fallback = HystrixClientFallback.class)
protected interface HystrixClient {
    @RequestMapping(method = RequestMethod.GET, value = "/hello")
    Hello iFailSometimes();
}

static class HystrixClientFallback implements HystrixClient {
    @Override
    public Hello iFailSometimes() {
        return new Hello("fallback");
    }
}
```

实现了`fallbackFactory`的版本

```java
@FeignClient(name = "hello", fallbackFactory = HystrixClientFallbackFactory.class)
protected interface HystrixClient {
	@RequestMapping(method = RequestMethod.GET, value = "/hello")
	Hello iFailSometimes();
}

@Component
static class HystrixClientFallbackFactory implements FallbackFactory<HystrixClient> {
	@Override
	public HystrixClient create(Throwable cause) {
		return new HystrixClient() {
			@Override
			public Hello iFailSometimes() {
				return new Hello("fallback; reason was: " + cause.getMessage());
			}
		};
	}
}
```

这里很明显啦，传进来的`throwable`对象就包含了原先抛出来的错误原因。

还有一个要注意的就是`@FeignClient`里的`fallback`属性一定要修改为`fallbackFactory`,毕竟改了之后就没有fallback这个东西了==